<?xml version="1.0" ?>
<!-- =================================================================================== -->
<!-- |    This document was autogenerated by xacro from 4wd.urdf.xacro                 | -->
<!-- |    EDITING THIS FILE BY HAND IS NOT RECOMMENDED                                 | -->
<!-- =================================================================================== -->
<robot name="linorobot2_2wd">
  <link name="base_footprint"/>
  <link name="base_link">
    <visual>
      <origin rpy="0 0 0" xyz="0 0 0"/>
      <geometry>
        <box size="0.445 0.2 0.129"/>
        <!-- <mesh filename="" scale="0.001 0.001 0.001"/> -->
      </geometry>
      <material name="yellow">
        <color rgba="0.8784 0.6627 0.6627 1.0"/>
      </material>
    </visual>
    <collision>
      <origin rpy="0 0 0" xyz="0 0 0"/>
      <geometry>
        <box size="0.445 0.2 0.129"/>
      </geometry>
    </collision>
    <inertial>
      <origin rpy="0 0 0" xyz="0 0 0"/>
      <mass value="10"/>
      <inertia ixx="0.04720083333333334" ixy="0.0" ixz="0.0" iyy="0.17888833333333332" iyz="0.0" izz="0.19835416666666666"/>
    </inertial>
  </link>
  <gazebo reference="base_link">
    <visual>
      <material>
        <ambient>0.8392 0.6314 0.0 1.0</ambient>
        <diffuse>0.8392 0.6314 0.0 1.0</diffuse>
        <specular>0.99 0.99 0.99 1.0</specular>
        <emissive>0.0 0.0 0.0 0.0</emissive>
      </material>
    </visual>
  </gazebo>
  <joint name="base_to_footprint" type="fixed">
    <parent link="base_footprint"/>
    <child link="base_link"/>
    <origin rpy="0 0 0" xyz="0 0 0.1195"/>
  </joint>
  <link name="front_left_wheel_link">
    <visual>
      <origin rpy="1.5707963267948966 0 0" xyz="0 0 0"/>
      <geometry>
        <cylinder length="0.05" radius="0.07162"/>
      </geometry>
      <material name="blue">
        <color rgba="0.1764 0.4588 0.8509 1.0"/>
      </material>
    </visual>
    <collision>
      <origin rpy="1.5707963267948966 0 0" xyz="0 0 0"/>
      <geometry>
        <cylinder length="0.05" radius="0.07162"/>
      </geometry>
    </collision>
    <inertial>
      <origin rpy="0 0 0" xyz="0 0 0"/>
      <mass value="0.6"/>
      <inertia ixx="0.0012310618560000001" ixy="0" ixz="0" iyy="0.0012310618560000001" iyz="0" izz="0.0012310618560000001"/>
    </inertial>
  </link>
  <gazebo reference="front_left_wheel_link">
    <visual>
      <material>
        <ambient>0.1764 0.4588 0.8509 1.0</ambient>
        <diffuse>0.1764 0.4588 0.8509 1.0</diffuse>
        <specular>0.1764 0.4588 0.8509 1.0</specular>
        <emissive>0.0 0.0 0.0 0.0</emissive>
      </material>
    </visual>
  </gazebo>
  <joint name="front_left_wheel_joint" type="continuous">
    <axis xyz="0 1 0"/>
    <parent link="base_link"/>
    <child link="front_left_wheel_link"/>
    <origin rpy="0 0 0" xyz="0.12 0.1355 -0.04788"/>
  </joint>
  <link name="front_right_wheel_link">
    <visual>
      <origin rpy="1.5707963267948966 0 0" xyz="0 0 0"/>
      <geometry>
        <cylinder length="0.05" radius="0.07162"/>
      </geometry>
      <material name="blue">
        <color rgba="0.1764 0.4588 0.8509 1.0"/>
      </material>
    </visual>
    <collision>
      <origin rpy="1.5707963267948966 0 0" xyz="0 0 0"/>
      <geometry>
        <cylinder length="0.05" radius="0.07162"/>
      </geometry>
    </collision>
    <inertial>
      <origin rpy="0 0 0" xyz="0 0 0"/>
      <mass value="0.6"/>
      <inertia ixx="0.0012310618560000001" ixy="0" ixz="0" iyy="0.0012310618560000001" iyz="0" izz="0.0012310618560000001"/>
    </inertial>
  </link>
  <gazebo reference="front_right_wheel_link">
    <visual>
      <material>
        <ambient>0.1764 0.4588 0.8509 1.0</ambient>
        <diffuse>0.1764 0.4588 0.8509 1.0</diffuse>
        <specular>0.1764 0.4588 0.8509 1.0</specular>
        <emissive>0.0 0.0 0.0 0.0</emissive>
      </material>
    </visual>
  </gazebo>
  <joint name="front_right_wheel_joint" type="continuous">
    <axis xyz="0 1 0"/>
    <parent link="base_link"/>
    <child link="front_right_wheel_link"/>
    <origin rpy="0 0 0" xyz="0.12 -0.1355 -0.04788"/>
  </joint>
  <link name="rear_left_wheel_link">
    <visual>
      <origin rpy="1.5707963267948966 0 0" xyz="0 0 0"/>
      <geometry>
        <cylinder length="0.05" radius="0.07162"/>
      </geometry>
      <material name="blue">
        <color rgba="0.1764 0.4588 0.8509 1.0"/>
      </material>
    </visual>
    <collision>
      <origin rpy="1.5707963267948966 0 0" xyz="0 0 0"/>
      <geometry>
        <cylinder length="0.05" radius="0.07162"/>
      </geometry>
    </collision>
    <inertial>
      <origin rpy="0 0 0" xyz="0 0 0"/>
      <mass value="0.6"/>
      <inertia ixx="0.0012310618560000001" ixy="0" ixz="0" iyy="0.0012310618560000001" iyz="0" izz="0.0012310618560000001"/>
    </inertial>
  </link>
  <gazebo reference="rear_left_wheel_link">
    <visual>
      <material>
        <ambient>0.1764 0.4588 0.8509 1.0</ambient>
        <diffuse>0.1764 0.4588 0.8509 1.0</diffuse>
        <specular>0.1764 0.4588 0.8509 1.0</specular>
        <emissive>0.0 0.0 0.0 0.0</emissive>
      </material>
    </visual>
  </gazebo>
  <joint name="rear_left_wheel_joint" type="continuous">
    <axis xyz="0 1 0"/>
    <parent link="base_link"/>
    <child link="rear_left_wheel_link"/>
    <origin rpy="0 0 0" xyz="-0.12 0.1355 -0.04788"/>
  </joint>
  <link name="rear_right_wheel_link">
    <visual>
      <origin rpy="1.5707963267948966 0 0" xyz="0 0 0"/>
      <geometry>
        <cylinder length="0.05" radius="0.07162"/>
      </geometry>
      <material name="blue">
        <color rgba="0.1764 0.4588 0.8509 1.0"/>
      </material>
    </visual>
    <collision>
      <origin rpy="1.5707963267948966 0 0" xyz="0 0 0"/>
      <geometry>
        <cylinder length="0.05" radius="0.07162"/>
      </geometry>
    </collision>
    <inertial>
      <origin rpy="0 0 0" xyz="0 0 0"/>
      <mass value="0.6"/>
      <inertia ixx="0.0012310618560000001" ixy="0" ixz="0" iyy="0.0012310618560000001" iyz="0" izz="0.0012310618560000001"/>
    </inertial>
  </link>
  <gazebo reference="rear_right_wheel_link">
    <visual>
      <material>
        <ambient>0.1764 0.4588 0.8509 1.0</ambient>
        <diffuse>0.1764 0.4588 0.8509 1.0</diffuse>
        <specular>0.1764 0.4588 0.8509 1.0</specular>
        <emissive>0.0 0.0 0.0 0.0</emissive>
      </material>
    </visual>
  </gazebo>
  <joint name="rear_right_wheel_joint" type="continuous">
    <axis xyz="0 1 0"/>
    <parent link="base_link"/>
    <child link="rear_right_wheel_link"/>
    <origin rpy="0 0 0" xyz="-0.12 -0.1355 -0.04788"/>
  </joint>
  <link name="imu_link"/>
  <joint name="imu_to_base_link" type="fixed">
    <parent link="base_link"/>
    <child link="imu_link"/>
    <origin rpy="0 0 0" xyz="0 0 0"/>
  </joint>
  <gazebo reference="imu_link">
    <gravity>true</gravity>
    <sensor name="imu_sensor" type="imu">
      <always_on>true</always_on>
      <update_rate>20</update_rate>
      <visualize>true</visualize>
      <topic>__default_topic__</topic>
      <plugin filename="libgazebo_ros_imu_sensor.so" name="imu_plugin">
        <ros>
          <remapping>~/out:=imu/data</remapping>
        </ros>
        <topicName>imu/data</topicName>
        <bodyName>imu_link</bodyName>
        <updateRateHZ>10.0</updateRateHZ>
        <gaussianNoise>0.0</gaussianNoise>
        <xyzOffset>0 0 0</xyzOffset>
        <rpyOffset>0 0 0</rpyOffset>
        <frameName>imu_link</frameName>
        <initialOrientationAsReference>false</initialOrientationAsReference>
      </plugin>
      <pose>0 0 0 0 0 0</pose>
    </sensor>
  </gazebo>
  <link name="laser">
    <visual>
      <origin rpy="0 0 0" xyz="0 0 -0.025"/>
      <geometry>
        <cylinder length="0.05" radius="0.0375"/>
      </geometry>
      <material name="green">
        <color rgba="0.003 0.639 0.223 1.0"/>
      </material>
    </visual>
    <collision>
      <origin rpy="0 0 0" xyz="0 0 -0.025"/>
      <geometry>
        <cylinder length="0.05" radius="0.0375"/>
      </geometry>
    </collision>
    <inertial>
      <origin rpy="0 0 0" xyz="0 0 0"/>
      <mass value="0.1"/>
      <inertia ixx="5.625000000000001e-05" ixy="0" ixz="0" iyy="5.625000000000001e-05" iyz="0" izz="5.625000000000001e-05"/>
    </inertial>
  </link>
  <gazebo reference="laser">
    <visual>
      <material>
        <ambient>0.003 0.639 0.223 1.0</ambient>
        <diffuse>0.003 0.639 0.223 1.0</diffuse>
        <specular>0.003 0.639 0.223 1.0</specular>
        <emissive>0.0 0.0 0.0 0.0</emissive>
      </material>
    </visual>
  </gazebo>
  <joint name="laser_to_base_link" type="fixed">
    <parent link="base_link"/>
    <child link="laser"/>
    <origin rpy="0 0 0" xyz="-0.0475 0 0.125"/>
  </joint>
  <gazebo reference="laser">
    <sensor name="laser_lidar" type="gpu_ray">
      <always_on>true</always_on>
      <update_rate>10</update_rate>
      <pose>0 0 0 0 0 0</pose>
      <visualize>false</visualize>
      <ray>
        <scan>
          <horizontal>
            <samples>360</samples>
            <resolution>1</resolution>
            <min_angle>-3.1416</min_angle>
            <max_angle>3.1416</max_angle>
          </horizontal>
        </scan>
        <range>
          <min>0.08</min>
          <max>12.0</max>
          <resolution>0.01</resolution>
        </range>
      </ray>
      <plugin filename="libgazebo_ros_ray_sensor.so" name="laser_lidar_controller">
        <ros>
          <remapping>~/out:=scan</remapping>
        </ros>
        <output_type>sensor_msgs/LaserScan</output_type>
        <alwaysOn>true</alwaysOn>
        <updateRate>10</updateRate>
        <topicName>scan</topicName>
        <frame_name>laser</frame_name>
        <output_type>sensor_msgs/LaserScan</output_type>
      </plugin>
    </sensor>
  </gazebo>
  <link name="camera_link">
    <visual>
      <origin rpy="0 0 0" xyz="0 0 0"/>
      <geometry>
        <box size="0.030 0.124 0.030"/>
        <!-- <mesh filename="" scale="0.001 0.001 0.001"/> -->
      </geometry>
      <material name="red">
        <color rgba="0.416 0.051 0.047 1.0"/>
      </material>
    </visual>
    <collision>
      <origin rpy="0 0 0" xyz="0 0 0"/>
      <geometry>
        <box size="0.030 0.124 0.030"/>
      </geometry>
    </collision>
    <inertial>
      <origin rpy="0 0 0" xyz="0 0 0"/>
      <mass value="0.135"/>
      <inertia ixx="0.00018310499999999998" ixy="0.0" ixz="0.0" iyy="2.0249999999999998e-05" iyz="0.0" izz="0.00018310499999999998"/>
    </inertial>
  </link>
  <gazebo reference="camera_link">
    <visual>
      <material>
        <ambient>0.416 0.051 0.047 1.0</ambient>
        <diffuse>0.416 0.051 0.047 1.0</diffuse>
        <specular>0.416 0.051 0.047 1.0</specular>
        <emissive>0.416 0.051 0.047 1.0</emissive>
      </material>
    </visual>
  </gazebo>
  rgb(213,28,40)

    
  <joint name="camera_to_base_link" type="fixed">
    <parent link="base_link"/>
    <child link="camera_link"/>
    <origin rpy="0 0 0" xyz="-0.065 0 0.255"/>
  </joint>
  <link name="camera_depth_link"/>
  <joint name="camera_depth_joint" type="fixed">
    <origin rpy="-1.57 0 -1.57" xyz="0 0 0"/>
    <parent link="camera_link"/>
    <child link="camera_depth_link"/>
  </joint>
  <!-- https://github.com/ros-simulation/gazebo_ros_pkgs/wiki/ROS-2-Migration:-Camera#gazebo_ros_camera -->
  <gazebo reference="camera_link">
    <sensor name="camera" type="depth">
      <always_on>true</always_on>
      <update_rate>30.0</update_rate>
      <camera name="camera">
        <horizontal_fov>1.50098</horizontal_fov>
        <image>
          <width>640</width>
          <height>480</height>
          <format>R8G8B8</format>
        </image>
      </camera>
      <plugin filename="libgazebo_ros_camera.so" name="camera_controller">
        <ros>
          <remapping>/camera/camera_info:=/camera/color/camera_info</remapping>
          <remapping>/camera/image_raw:=/camera/color/image_raw</remapping>
          <remapping>/camera/points:=/camera/depth/color/points</remapping>
          <remapping>/camera/depth/image_raw:=/camera/depth/image_rect_raw</remapping>
          <qos>
            <topic name="/camera/depth/color/points">
              <publisher>
                <reliability>best_effort</reliability>
              </publisher>
            </topic>
          </qos>
        </ros>
        <min_depth>0.015</min_depth>
        <max_depth>3.0</max_depth>
        <hack_baseline>0.07</hack_baseline>
        <frame_name>camera_depth_link</frame_name>
        <distortion_k1>0.00000001</distortion_k1>
        <distortion_k2>0.00000001</distortion_k2>
        <distortion_k3>0.00000001</distortion_k3>
        <distortion_t1>0.00000001</distortion_t1>
        <distortion_t2>0.00000001</distortion_t2>
      </plugin>
    </sensor>
  </gazebo>
  <gazebo>
    <plugin filename="libgazebo_ros_diff_drive.so" name="differential_drive_controller">
      <ros>
        <remapping>odom:=odom/unfiltered</remapping>
      </ros>
      <num_wheel_pairs>2</num_wheel_pairs>
      <left_joint>front_left_wheel_joint</left_joint>
      <right_joint>front_right_wheel_joint</right_joint>
      <left_joint>rear_left_wheel_joint</left_joint>
      <right_joint>rear_right_wheel_joint</right_joint>
      <wheel_separation>0.271</wheel_separation>
      <wheel_separation>0.271</wheel_separation>
      <wheel_diameter>0.14324</wheel_diameter>
      <wheel_diameter>0.14324</wheel_diameter>
      <updateRate>100</updateRate>
      <max_wheel_acceleration>1.0</max_wheel_acceleration>
      <robot_base_frame>base_footprint</robot_base_frame>
      <publish_odom>true</publish_odom>
      <publish_odom_tf>false</publish_odom_tf>
      <publish_wheel_tf>true</publish_wheel_tf>
      <odometry_frame>odom</odometry_frame>
    </plugin>
  </gazebo>
</robot>
