<?xml version="1.0" ?>
<!-- =================================================================================== -->
<!-- |    This document was autogenerated by xacro from robot.urdf.xacro               | -->
<!-- |    EDITING THIS FILE BY HAND IS NOT RECOMMENDED                                 | -->
<!-- =================================================================================== -->
<robot name="robot">
  <!-- Specify some standard inertial calculations https://en.wikipedia.org/wiki/List_of_moments_of_inertia -->
  <!-- These make use of xacro's mathematical functionality -->
  <material name="white">
    <color rgba="1.0 1.0 1.0 1.0"/>
  </material>
  <material name="black">
    <color rgba="0.0 0.0 0.0 1.0"/>
  </material>
  <material name="red">
    <color rgba="1.0 0.0 0.0 1.0"/>
  </material>
  <material name="yellow">
    <color rgba="1.0 1.0 0.0 1.0"/>
  </material>
  <material name="blue">
    <color rgba="0.0 1.0 1.0 1.0"/>
  </material>
  <material name="green">
    <color rgba="0.0 1.0 0.0 1.0"/>
  </material>
  <link name="base_link">
    
</link>
  <!-- Chassis part 1 -->
  <joint name="chassis1_joint" type="fixed">
    <parent link="base_link"/>
    <child link="chassis1"/>
    <origin xyz="0.0 0.0 0.0"/>
  </joint>
  <link name="chassis1">
    <visual>
      <origin xyz="0.0225 0.0 0.045"/>
      <geometry>
        <box size="0.045 0.15 0.0025"/>
      </geometry>
      <material name="white"/>
    </visual>
    <collision>
      <origin xyz="0.0225 0 0.045"/>
      <geometry>
        <box size="0.045 0.15 0.0025"/>
      </geometry>
    </collision>
    <inertial>
      <origin rpy="0.0 0.0 0.0" xyz="0.0225 0.0 0.045"/>
      <mass value="0.0084375"/>
      <inertia ixx="1.5824707031249997e-05" ixy="0.0" ixz="0.0" iyy="1.42822265625e-06" iyz="0.0" izz="1.7244140624999997e-05"/>
    </inertial>
  </link>
  <gazebo reference="chassis1">
    <material>Gazebo/White</material>
  </gazebo>
  <!-- Chassis part 2 -->
  <joint name="chassis2_joint" type="fixed">
    <parent link="chassis1"/>
    <child link="chassis2"/>
    <origin xyz="0.0825 0.0 0.045"/>
  </joint>
  <link name="chassis2">
    <visual>
      <geometry>
        <box size="0.075 0.09 0.0025"/>
      </geometry>
      <material name="white"/>
    </visual>
    <collision>
      <geometry>
        <box size="0.075 0.09 0.0025"/>
      </geometry>
    </collision>
    <inertial>
      <origin rpy="0.0 0.0 0.0" xyz="0.0825 0.0 0.045"/>
      <mass value="0.0084375"/>
      <inertia ixx="5.699707031249999e-06" ixy="0.0" ixz="0.0" iyy="3.95947265625e-06" iyz="0.0" izz="9.650390624999998e-06"/>
    </inertial>
  </link>
  <gazebo reference="chassis2">
    <material>Gazebo/White</material>
  </gazebo>
  <!-- Chassis part 3 -->
  <joint name="chassis3_joint" type="fixed">
    <parent link="chassis2"/>
    <child link="chassis3"/>
    <origin xyz="0.0475 0.0 0.0"/>
  </joint>
  <link name="chassis3">
    <visual>
      <geometry>
        <box size="0.02 0.15 0.0025"/>
      </geometry>
      <material name="white"/>
    </visual>
    <collision>
      <geometry>
        <box size="0.02 0.15 0.0025"/>
      </geometry>
    </collision>
    <inertial>
      <origin rpy="0.0 0.0 0.0" xyz="0.0475 0.0 0.0"/>
      <mass value="0.00375"/>
      <inertia ixx="7.033203124999998e-06" ixy="0.0" ixz="0.0" iyy="1.26953125e-07" iyz="0.0" izz="7.156249999999999e-06"/>
    </inertial>
  </link>
  <gazebo reference="chassis3">
    <material>Gazebo/White</material>
  </gazebo>
  <!-- Chassis part 4 -->
  <joint name="chassis4_joint" type="fixed">
    <parent link="chassis3"/>
    <child link="chassis4"/>
    <origin xyz="0.0475 0.0 0.0"/>
  </joint>
  <link name="chassis4">
    <visual>
      <geometry>
        <box size="0.075 0.09 0.0025"/>
      </geometry>
      <material name="white"/>
    </visual>
    <collision>
      <geometry>
        <box size="0.075 0.09 0.0025"/>
      </geometry>
    </collision>
    <inertial>
      <origin rpy="0.0 0.0 0.0" xyz="0.0475 0.0 0.0"/>
      <mass value="0.0084375"/>
      <inertia ixx="5.699707031249999e-06" ixy="0.0" ixz="0.0" iyy="3.95947265625e-06" iyz="0.0" izz="9.650390624999998e-06"/>
    </inertial>
  </link>
  <gazebo reference="chassis4">
    <material>Gazebo/White</material>
  </gazebo>
  <!-- Chassis part 5 -->
  <joint name="chassis5_joint" type="fixed">
    <parent link="chassis4"/>
    <child link="chassis5"/>
    <origin xyz="0.06 0.0 0.0"/>
  </joint>
  <link name="chassis5">
    <visual>
      <geometry>
        <box size="0.045 0.15 0.0025"/>
      </geometry>
      <material name="white"/>
    </visual>
    <collision>
      <geometry>
        <box size="0.045 0.15 0.0025"/>
      </geometry>
    </collision>
    <inertial>
      <origin rpy="0.0 0.0 0.0" xyz="0.06 0.0 0.0"/>
      <mass value="0.00375"/>
      <inertia ixx="7.033203124999998e-06" ixy="0.0" ixz="0.0" iyy="6.34765625e-07" iyz="0.0" izz="7.664062499999999e-06"/>
    </inertial>
  </link>
  <gazebo reference="chassis5">
    <material>Gazebo/White</material>
  </gazebo>
  <!-- Chassis part 1 -->
  <joint name="chassis11_joint" type="fixed">
    <parent link="base_link"/>
    <child link="chassis11"/>
    <origin xyz="0.0 0.0 0.0"/>
  </joint>
  <link name="chassis11">
    <visual>
      <origin xyz="0.0225 0.0 0.096"/>
      <geometry>
        <box size="0.045 0.15 0.0025"/>
      </geometry>
      <material name="white"/>
    </visual>
    <collision>
      <origin xyz="0.0225 0 0.096"/>
      <geometry>
        <box size="0.045 0.15 0.0025"/>
      </geometry>
    </collision>
    <inertial>
      <origin rpy="0.0 0.0 0.0" xyz="0.0225 0.0 0.096"/>
      <mass value="0.0084375"/>
      <inertia ixx="1.5824707031249997e-05" ixy="0.0" ixz="0.0" iyy="1.42822265625e-06" iyz="0.0" izz="1.7244140624999997e-05"/>
    </inertial>
  </link>
  <gazebo reference="chassis11">
    <material>Gazebo/White</material>
  </gazebo>
  <!-- Chassis part 2 -->
  <joint name="chassis21_joint" type="fixed">
    <parent link="chassis1"/>
    <child link="chassis21"/>
    <origin xyz="0.0825 0.0 0.096"/>
  </joint>
  <link name="chassis21">
    <visual>
      <geometry>
        <box size="0.075 0.09 0.0025"/>
      </geometry>
      <material name="white"/>
    </visual>
    <collision>
      <geometry>
        <box size="0.075 0.09 0.0025"/>
      </geometry>
    </collision>
    <inertial>
      <origin rpy="0.0 0.0 0.0" xyz="0.0825 0.0 0.096"/>
      <mass value="0.0084375"/>
      <inertia ixx="5.699707031249999e-06" ixy="0.0" ixz="0.0" iyy="3.95947265625e-06" iyz="0.0" izz="9.650390624999998e-06"/>
    </inertial>
  </link>
  <gazebo reference="chassis21">
    <material>Gazebo/White</material>
  </gazebo>
  <!-- Chassis part 3 -->
  <joint name="chassis31_joint" type="fixed">
    <parent link="chassis2"/>
    <child link="chassis31"/>
    <origin xyz="0.0475 0.0 0.051"/>
  </joint>
  <link name="chassis31">
    <visual>
      <geometry>
        <box size="0.04 0.15 0.0025"/>
      </geometry>
      <material name="white"/>
    </visual>
    <collision>
      <geometry>
        <box size="0.04 0.15 0.0025"/>
      </geometry>
    </collision>
    <inertial>
      <origin rpy="0.0 0.0 0.0" xyz="0.0475 0.0 0.051"/>
      <mass value="0.0075"/>
      <inertia ixx="1.4066406249999997e-05" ixy="0.0" ixz="0.0" iyy="1.0039062499999998e-06" iyz="0.0" izz="1.5062499999999997e-05"/>
    </inertial>
  </link>
  <gazebo reference="chassis31">
    <material>Gazebo/White</material>
  </gazebo>
  <!-- Chassis part 4 -->
  <joint name="chassis41_joint" type="fixed">
    <parent link="chassis3"/>
    <child link="chassis41"/>
    <origin xyz="0.0475 0.0 0.051"/>
  </joint>
  <link name="chassis41">
    <visual>
      <geometry>
        <box size="0.075 0.09 0.0025"/>
      </geometry>
      <material name="white"/>
    </visual>
    <collision>
      <geometry>
        <box size="0.075 0.09 0.0025"/>
      </geometry>
    </collision>
    <inertial>
      <origin rpy="0.0 0.0 0.0" xyz="0.0475 0.0 0.051"/>
      <mass value="0.0084375"/>
      <inertia ixx="5.699707031249999e-06" ixy="0.0" ixz="0.0" iyy="3.95947265625e-06" iyz="0.0" izz="9.650390624999998e-06"/>
    </inertial>
  </link>
  <gazebo reference="chassis41">
    <material>Gazebo/White</material>
  </gazebo>
  <!-- Chassis part 5 -->
  <joint name="chassis51_joint" type="fixed">
    <parent link="chassis4"/>
    <child link="chassis51"/>
    <origin xyz="0.06 0.0 0.051"/>
  </joint>
  <link name="chassis51">
    <visual>
      <geometry>
        <box size="0.045 0.15 0.0025"/>
      </geometry>
      <material name="white"/>
    </visual>
    <collision>
      <geometry>
        <box size="0.045 0.15 0.0025"/>
      </geometry>
    </collision>
    <inertial>
      <origin rpy="0.0 0.0 0.0" xyz="0.06 0.0 0.051"/>
      <mass value="0.00375"/>
      <inertia ixx="7.033203124999998e-06" ixy="0.0" ixz="0.0" iyy="6.34765625e-07" iyz="0.0" izz="7.664062499999999e-06"/>
    </inertial>
  </link>
  <gazebo reference="chassis51">
    <material>Gazebo/White</material>
  </gazebo>
  <!-- Ultrasonic sensor -->
  <joint name="supprot_ultrasoni_joint" type="fixed">
    <parent link="chassis51"/>
    <child link="supprot_ultr"/>
    <origin xyz="0.02 0.0 0.01065"/>
    <!-- <origin xyz="0.0 0.0 0.1"/> -->
  </joint>
  <link name="supprot_ultr">
    <visual>
      <geometry>
        <box size="0.0025 0.0457 0.0213"/>
      </geometry>
      <material name="blue"/>
    </visual>
    <collision>
      <geometry>
        <box size="0.0025 0.0457 0.0213"/>
      </geometry>
    </collision>
    <inertial>
      <origin rpy="0.0 0.0 0.0" xyz="0.02 0.0 0.01065"/>
      <mass value="0.00375"/>
      <inertia ixx="7.944312499999998e-07" ixy="0.0" ixz="0.0" iyy="1.4373124999999999e-07" iyz="0.0" izz="6.546062499999999e-07"/>
    </inertial>
  </link>
  <gazebo reference="supprot_ultr">
    <material>Gazebo/Blue</material>
  </gazebo>
  <!-- Ultrasonic Trigger -->
  <joint name="supprot_trigger_joint" type="fixed">
    <parent link="supprot_ultr"/>
    <child link="supprot_trigger"/>
    <origin rpy="0.0 1.5707963267948966 0.0" xyz="0.006 0.01235 0.0"/>
  </joint>
  <link name="supprot_trigger">
    <visual>
      <geometry>
        <cylinder length="0.012" radius="0.008"/>
      </geometry>
      <material name="white"/>
    </visual>
    <collision>
      <geometry>
        <cylinder length="0.012" radius="0.008"/>
      </geometry>
    </collision>
    <inertial>
      <origin rpy="0.0 1.5707963267948966 0.0" xyz="0.006 0.01235 0.0"/>
      <mass value="0.0012063715789784805"/>
      <inertia ixx="3.3778404211397457e-08" ixy="0.0" ixz="0.0" iyy="3.3778404211397457e-08" iyz="0.0" izz="3.860389052731137e-08"/>
    </inertial>
  </link>
  <gazebo reference="supprot_trigger">
    <material>Gazebo/White</material>
  </gazebo>
  <!-- Ultrasonic Echo -->
  <joint name="supprot_echo_joint" type="fixed">
    <parent link="supprot_ultr"/>
    <child link="supprot_echo"/>
    <origin rpy="0.0 1.5707963267948966 0.0" xyz="0.006 -0.01235 0.0"/>
  </joint>
  <link name="supprot_echo">
    <visual>
      <geometry>
        <cylinder length="0.012" radius="0.008"/>
      </geometry>
      <material name="white"/>
    </visual>
    <collision>
      <geometry>
        <cylinder length="0.012" radius="0.008"/>
      </geometry>
    </collision>
    <inertial>
      <origin rpy="0.0 1.5707963267948966 0.0" xyz="0.006 -0.01235 0.0"/>
      <mass value="0.0012063715789784805"/>
      <inertia ixx="3.3778404211397457e-08" ixy="0.0" ixz="0.0" iyy="3.3778404211397457e-08" iyz="0.0" izz="3.860389052731137e-08"/>
    </inertial>
  </link>
  <gazebo reference="supprot_echo">
    <material>Gazebo/White</material>
  </gazebo>
  <!-- *********************** ULTRASONIC SENSOR ************************  -->
  <joint name="ultrasonic_optical_joint" type="fixed">
    <parent link="supprot_ultr"/>
    <child link="ultrasonic_link_optical"/>
    <origin rpy="-1.5707963267948966 0 -1.5707963267948966" xyz="0 0 0"/>
  </joint>
  <link name="ultrasonic_link_optical"/>
  <gazebo reference="supprot_ultr">
    <sensor name="ultrasonic_1" type="ray">
      <pose> 0 0 0 0 0 0 </pose>
      <always_on>true</always_on>
      <visualize>false</visualize>
      <update_rate>5</update_rate>
      <ray>
        <scan>
          <horizontal>
            <samples>5</samples>
            <resolution>1.000000</resolution>
            <min_angle>-0.12</min_angle>
            <max_angle>0.12</max_angle>
          </horizontal>
          <vertical>
            <samples>5</samples>
            <resolution>1.000000</resolution>
            <min_angle>-0.01</min_angle>
            <max_angle>0.01</max_angle>
          </vertical>
        </scan>
        <range>
          <min>0.02</min>
          <max>4</max>
          <resolution>0.01</resolution>
        </range>
        <noise>
          <type>gaussian</type>
          <mean>0.0</mean>
          <stddev>0.01</stddev>
        </noise>
      </ray>
      <plugin filename="libgazebo_ros_ray_sensor.so" name="ultrasonic_sensor_1">
        <ros>
          <remapping>~/out:=ultrasonic_sensor_1</remapping>
        </ros>
        <output_type>sensor_msgs/Range</output_type>
        <radiation_type>ultrasound</radiation_type>
        <frame_name>ultrasonic_link_optical</frame_name>
      </plugin>
    </sensor>
  </gazebo>
  <!-- *********************** ULTRASONIC SENSOR ************************  -->
  <!-- <link name="supprot_ultr2">
  <pose>0.09 -0.139 0.595 0 0 0</pose>
  <sensor name="ultrasonic_1" type="ray">
    <always_on>true</always_on>
    <visualize>false</visualize>
    <update_rate>5</update_rate>
    <ray>
      <scan>
        <horizontal>
          <samples>5</samples>
          <resolution>1.000000</resolution>
          <min_angle>-0.12</min_angle>
          <max_angle>0.12</max_angle>
        </horizontal>
        <vertical>
          <samples>5</samples>
          <resolution>1.000000</resolution>
          <min_angle>-0.01</min_angle>
          <max_angle>0.01</max_angle>
        </vertical>
      </scan>
      <range>
        <min>0.02</min>
        <max>4</max>
        <resolution>0.01</resolution>
      </range>
      <noise>
        <type>gaussian</type>
        <mean>0.0</mean>
        <stddev>0.01</stddev>
      </noise>
    </ray>
    <plugin name="ultrasonic_sensor_1" filename="libgazebo_ros_ray_sensor.so">
      <ros>
        <remapping>~/out:=ultrasonic_sensor_1</remapping>
      </ros>
      <output_type>sensor_msgs/Range</output_type>
      <radiation_type>ultrasound</radiation_type>
      <frame_name>supprot_ultr</frame_name>
    </plugin>
  </sensor>  
</link> -->
  <!-- Batterie -->
  <joint name="batterie_joint" type="fixed">
    <parent link="chassis3"/>
    <child link="batterie"/>
    <origin xyz="0.0 0.0 0.01375"/>
  </joint>
  <link name="batterie">
    <visual>
      <geometry>
        <box size="0.1375 0.045 0.025"/>
      </geometry>
      <material name="black"/>
    </visual>
    <collision>
      <geometry>
        <box size="0.1375 0.045 0.025"/>
      </geometry>
    </collision>
    <inertial>
      <origin rpy="0.0 0.0 0.0" xyz="0.0 0.0 0.01375"/>
      <mass value="0.5"/>
      <inertia ixx="1.1041667e-04" ixy="0.0" ixz="0.0" iyy="8.1380208e-04" iyz="0.0" izz="8.7213542e-04"/>
    </inertial>
  </link>
  <gazebo reference="batterie">
    <material>Gazebo/Black</material>
  </gazebo>
<!--   <gazebo>
    <plugin filename="libgazebo_ros_diff_drive.so" name="diff_drive">
      <left_joint> rear_left_wheel_joint </left_joint>
      <right_joint> rear_right_wheel_joint </right_joint>
      <wheel_separation>0.12</wheel_separation>
      <wheel_diameter>0.067</wheel_diameter>
      <max_wheel_torque>200</max_wheel_torque>
      <max_wheel_acceleration>10.0</max_wheel_acceleration>
      <odometry_frame>odom</odometry_frame>
      <robot_base_frame>base_link</robot_base_frame>
      <publish_odom>true</publish_odom>
      <publish_odom_tf>true</publish_odom_tf>
      <publish_wheel_tf>true</publish_wheel_tf>
    </plugin>
  </gazebo> -->

  <!-- <gazebo>
        <plugin name="skid_steer_drive_controller" filename="libgazebo_ros_skid_steer_drive.so">
        <updateRate>10.0</updateRate>
        <robotBaseFrame>/base_link</robotBaseFrame>
        <wheelSeparation>0.12</wheelSeparation>
        <wheelDiameter>0.067</wheelDiameter>
        <torque>5</torque>
        <leftFrontJoint>caster_wheel1_joint</leftFrontJoint>
        <rightFrontJoint>caster_wheel2_joint</rightFrontJoint>
        <leftRearJoint>rear_left_wheel_joint</leftRearJoint>
        <rightRearJoint>rear_right_wheel_joint</rightRearJoint>
        <topicName>cmd_vel</topicName>
        <commandTopic>cmd_vel</commandTopic>
        <broadcastTF>true</broadcastTF>
        <odometryTopic>odom</odometryTopic>
        <odometryFrame>/odom</odometryFrame>
        <covariance_x>0.000100</covariance_x>
        <covariance_y>0.000100</covariance_y>
        <covariance_yaw>0.010000</covariance_yaw>
        </plugin>
    </gazebo> -->
  <joint name="camera_joint1" type="fixed">
    <parent link="chassis41"/>
    <child link="camera_link1"/>
    <origin rpy="0 0 0" xyz="-0.0175 0 0.0025"/>
  </joint>
  <link name="camera_link1">
    <visual>
      <geometry>
        <box size="0.02 0.02 0.0025"/>
      </geometry>
      <material name="red"/>
    </visual>
    <collision>
      <geometry>
        <box size="0.02 0.02 0.0025"/>
      </geometry>
    </collision>
    <inertial>
      <origin rpy="0.0 0.0 0.0" xyz="-0.0175 0.0 0.0025"/>
      <mass value="0.0005"/>
      <inertia ixx="1.6927083333333336e-08" ixy="0.0" ixz="0.0" iyy="1.6927083333333336e-08" iyz="0.0" izz="3.3333333333333334e-08"/>
    </inertial>
  </link>
  <joint name="camera_joint2" type="fixed">
    <parent link="camera_link1"/>
    <child link="camera_link2"/>
    <origin rpy="0 0 0" xyz="0.015 0.0 0.00375"/>
  </joint>
  <link name="camera_link2">
    <visual>
      <geometry>
        <box size="0.01 0.02 0.01"/>
      </geometry>
      <material name="red"/>
    </visual>
    <collision>
      <geometry>
        <box size="0.01 0.02 0.01"/>
      </geometry>
    </collision>
    <inertial>
      <origin rpy="0.0 0.0 0.0" xyz="0.015 0.0 0.00375"/>
      <mass value="0.001"/>
      <inertia ixx="4.166666666666667e-08" ixy="0.0" ixz="0.0" iyy="1.6666666666666667e-08" iyz="0.0" izz="4.166666666666667e-08"/>
    </inertial>
  </link>
  <joint name="camera_joint3" type="fixed">
    <parent link="camera_link2"/>
    <child link="camera_link3"/>
    <origin rpy="0 0 0" xyz="-0.005 0 0.009"/>
  </joint>
  <link name="camera_link3">
    <visual>
      <geometry>
        <box size="0.04 0.02 0.008"/>
      </geometry>
      <material name="red"/>
    </visual>
    <collision>
      <geometry>
        <box size="0.04 0.02 0.008"/>
      </geometry>
    </collision>
    <inertial>
      <origin rpy="0.0 0.0 0.0" xyz="-0.005 0 0.009"/>
      <mass value="0.0032"/>
      <inertia ixx="1.2373333333333333e-07" ixy="0.0" ixz="0.0" iyy="4.437333333333334e-07" iyz="0.0" izz="5.333333333333333e-07"/>
    </inertial>
  </link>
  <joint name="camera_joint4" type="fixed">
    <parent link="camera_link3"/>
    <child link="camera_link4"/>
    <origin rpy="0 0.775193 0" xyz="0.04 0 0.0245"/>
  </joint>
  <link name="camera_link4">
    <visual>
      <geometry>
        <box size="0.005 0.02 0.07"/>
      </geometry>
      <material name="red"/>
    </visual>
    <collision>
      <geometry>
        <box size="0.005 0.02 0.07"/>
      </geometry>
    </collision>
    <inertial>
      <origin rpy="0.0 0.775193 0.0" xyz="0.04 0 0.0245"/>
      <mass value="0.0035"/>
      <inertia ixx="1.5458333333333335e-06" ixy="0.0" ixz="0.0" iyy="1.4364583333333334e-06" iyz="0.0" izz="1.2395833333333332e-07"/>
    </inertial>
  </link>
  <joint name="camera_joint5" type="fixed">
    <parent link="camera_link3"/>
    <child link="camera_link5"/>
    <origin rpy="0 0 0" xyz="0.0725 0 0.0487"/>
  </joint>
  <link name="camera_link5">
    <visual>
      <geometry>
        <box size="0.02 0.02 0.005"/>
      </geometry>
      <material name="red"/>
    </visual>
    <collision>
      <geometry>
        <box size="0.02 0.02 0.005"/>
      </geometry>
    </collision>
    <inertial>
      <origin rpy="0.0 0.0 0.0" xyz="0.0725 0 0.0487"/>
      <mass value="0.001"/>
      <inertia ixx="3.541666666666667e-08" ixy="0.0" ixz="0.0" iyy="3.541666666666667e-08" iyz="0.0" izz="6.666666666666667e-08"/>
    </inertial>
  </link>
  <joint name="camera_joint6" type="fixed">
    <parent link="camera_link5"/>
    <child link="camera_link6"/>
    <origin rpy="0 0 0" xyz="0 0 0.0275"/>
  </joint>
  <link name="camera_link6">
    <visual>
      <geometry>
        <cylinder length="0.05" radius="0.004"/>
      </geometry>
      <material name="red"/>
    </visual>
    <collision>
      <geometry>
        <cylinder length="0.05" radius="0.004"/>
      </geometry>
    </collision>
    <inertial>
      <origin rpy="0.0 0.0 0.0" xyz="0 0 0.0275"/>
      <mass value="0.001256637"/>
      <inertia ixx="2.66825923e-07" ixy="0.0" ixz="0.0" iyy="2.66825923e-07" iyz="0.0" izz="1.0053095999999998e-08"/>
    </inertial>
  </link>
  <joint name="camera_joint7" type="fixed">
    <parent link="camera_link6"/>
    <child link="camera_link7"/>
    <origin rpy="0 0 0" xyz="0 0 0.032"/>
  </joint>
  <link name="camera_link7">
    <visual>
      <geometry>
        <cylinder length="0.014" radius="0.009"/>
      </geometry>
      <material name="red"/>
    </visual>
    <collision>
      <geometry>
        <cylinder length="0.014" radius="0.009"/>
      </geometry>
    </collision>
    <inertial>
      <origin rpy="0.0 0.0 0.0" xyz="0 0 0.032"/>
      <mass value="0.001781283"/>
      <inertia ixx="3.7822575700000003e-07" ixy="0.0" ixz="0.0" iyy="3.7822575700000003e-07" iyz="0.0" izz="1.4250264e-08"/>
    </inertial>
  </link>
  <joint name="camera_joint8" type="fixed">
    <parent link="camera_link7"/>
    <child link="camera_link8"/>
    <origin rpy="0 0 0" xyz="0.0 0.0 0.02"/>
  </joint>
  <link name="camera_link8">
    <visual>
      <geometry>
        <box size="0.01 0.034 0.03"/>
      </geometry>
      <material name="red"/>
    </visual>
    <collision>
      <geometry>
        <box size="0.01 0.034 0.03"/>
      </geometry>
    </collision>
    <inertial>
      <origin rpy="0.0 0 0.0" xyz="0.0 0.0 0.02"/>
      <mass value="0.0051"/>
      <inertia ixx="8.738000000000001e-07" ixy="0.0" ixz="0.0" iyy="4.2500000000000006e-07" iyz="0.0" izz="5.338000000000001e-07"/>
    </inertial>
  </link>
  <joint name="camera_optical_joint" type="fixed">
    <parent link="camera_link8"/>
    <child link="camera_link_optical"/>
    <origin rpy="-1.5707963267948966 0 -1.5707963267948966" xyz="0 0 0"/>
  </joint>
 <link name="camera_link_optical"/>

<!-- Camera simple + depth camer -->

  <gazebo reference="camera_link8">
    <material>Gazebo/Red</material>
    <sensor name="camera" type="depth">
      <pose> 0 0 0 0 0 0 </pose>
      <visualize>false</visualize>
      <update_rate>10</update_rate>
      <camera>
        <horizontal_fov>1.1519</horizontal_fov>
        <image>
          <format>B8G8R8</format>
          <width>640</width>
          <height>480</height>
        </image>
        <clip>
          <near>0.03</near>
          <far>8.0</far>
        </clip>
      </camera>
      <plugin filename="libgazebo_ros_camera.so" name="camera_controller">
        <frame_name>camera_link_optical</frame_name>
        <min_depth>0.1</min_depth>
        <max_depth>100.0</max_depth>
      </plugin>
    </sensor>
  </gazebo> 
<!-- camera_fish 

 <gazebo reference="camera_link8">
    <sensor name="camera" type="wideanglecamera">
      <update_rate>30.0</update_rate>
      <camera>
        <horizontal_fov>3.84</horizontal_fov>
        <image>
          <width>640</width>
          <height>480</height>
          <format>B8G8R8</format>
        </image>
        <clip>
          <near>0.01</near>
          <far>10</far>
        </clip>
        <lens>
          <type>custom</type>
          <custom_function>
            <c1>3</c1>
            <c2>8</c2>
            <f>1.0</f>
            <fun>tan</fun>
          </custom_function>
          <scale_to_hfov>true</scale_to_hfov>
          <env_texture_size>512</env_texture_size>
        </lens>
        <noise>
          <type>gaussian</type>
          <mean>0.0</mean>
          <stddev>0.05</stddev>
        </noise>
      </camera>
      <plugin filename="libgazebo_ros_camera.so" name="camera_plugin">
        <baseline>0.2</baseline>
        <alwaysOn>true</alwaysOn>
        <updateRate>0</updateRate>
        <cameraName>camera_fish</cameraName>
        <imageTopicName>/camera/fisheye/image_raw</imageTopicName>
        <cameraInfoTopicName>/camera/fisheye/camera_info</cameraInfoTopicName>
        <frameName>camera_link_optical</frameName>
        <pointCloudCutoff>0.01</pointCloudCutoff>
        <distortionK1>-0.8</distortionK1>
        <distortionK2>0.12</distortionK2>
        <distortionK3>10</distortionK3>
        <distortionT1>0</distortionT1>
        <distortionT2>0</distortionT2>
        <CxPrime>0</CxPrime>
        <Cx>0</Cx>
        <Cy>0</Cy>
        <focalLength>0</focalLength>
        <hackBaseline>0</hackBaseline>
      </plugin>
    </sensor>
  </gazebo> -->


  <!-- rear left 0.065-->
  <joint name="rear_left_wheel_joint" type="continuous">
    <parent link="base_link"/>
    <child link="rear_left"/>
    <origin rpy="-1.5707963267948966 0 0" xyz="0.0825 0.0625 0.0335"/> 
    <axis xyz="0 0 1"/>
  </joint>
  <link name="rear_left">
    <visual>
      <geometry>
        <cylinder length="0.025" radius="0.0335"/>
      </geometry>
      <material name="black"/>
    </visual>
    <collision>
      <geometry>
        <cylinder length="0.025" radius="0.0335"/>
      </geometry>
    </collision>
    <inertial>
      <origin xyz="0 0 0"/>
      <mass value="0.1"/>
      <inertia ixx="0.000033264583" ixy="0.0" ixz="0.0" iyy="0.000033264583" iyz="0.0" izz="0.00002805625"/>
    </inertial>
  </link>
  <gazebo reference="rear_left">
    <material>Gazebo/Black</material>
<!--     <mu1 value="10000.0"/>
    <mu2 value="10000.0"/> -->
  </gazebo>
  <!-- rear right-->
  <joint name="rear_right_wheel_joint" type="continuous">
    <parent link="base_link"/>
    <child link="rear_right"/>
    <origin rpy="1.5707963267948966 0 0" xyz="0.0825 -0.0625 0.0335"/> 
    <axis xyz="0 0 -1"/>
  </joint>
  <link name="rear_right">
    <visual>
      <geometry>
        <cylinder length="0.025" radius="0.0335"/>
      </geometry>
      <material name="black"/>
    </visual>
    <collision>
      <geometry>
        <cylinder length="0.025" radius="0.0335"/>
      </geometry>
    </collision>
    <inertial>
     <origin xyz="0 0 0"/>
      <mass value="0.1"/>
      <inertia ixx="0.000033264583" ixy="0.0" ixz="0.0" iyy="0.000033264583" iyz="0.0" izz="0.00002805625"/>
    </inertial>
  </link>
  <gazebo reference="rear_right">
    <material>Gazebo/Black</material>
<!--     <mu1 value="10000.0"/>
    <mu2 value="10000.0"/> -->
  </gazebo>
  <!-- front left-->
  <joint name="front_left_wheel_joint" type="continuous">
    <parent link="base_link"/>
    <child link="front_left"/>
    <origin rpy="-1.5707963267948966 0 0" xyz="0.1775 0.0625 0.0335"/> 
    <axis xyz="0 0 1"/> 
  </joint>
  <link name="front_left">
    <visual>
      <geometry>
        <cylinder length="0.025" radius="0.0335"/>
      </geometry>
      <material name="black"/>
    </visual>
    <collision>
      <geometry>
        <cylinder length="0.025" radius="0.0335"/>
      </geometry>
    </collision>
    <inertial>
      <origin xyz="0 0 0"/>
      <mass value="0.1"/>
      <inertia ixx="0.000033264583" ixy="0.0" ixz="0.0" iyy="0.000033264583" iyz="0.0" izz="0.00002805625"/>
    </inertial>
  </link>
  <gazebo reference="front_left">
    <material>Gazebo/Black</material>
    <!-- <mu1 value="0.000001"/>
    <mu2 value="0.000001"/> -->
  </gazebo>
  <!-- front right-->
  <joint name="front_right_wheel_joint" type="continuous">
    <parent link="base_link"/>
    <child link="front_right"/>
    <origin rpy="1.5707963267948966 0 0" xyz="0.1775 -0.0625 0.0335"/> 
    <axis xyz="0 0 -1"/> 
  </joint>
  <link name="front_right">
    <visual>
      <geometry>
        <cylinder length="0.025" radius="0.0335"/>
      </geometry>
      <material name="black"/>
    </visual>
    <collision>
      <geometry>
        <cylinder length="0.025" radius="0.0335"/>
      </geometry>
    </collision>
    <inertial>
      <origin xyz="0 0 0"/>
      <mass value="0.1"/>
      <inertia ixx="0.000033264583" ixy="0.0" ixz="0.0" iyy="0.000033264583" iyz="0.0" izz="0.00002805625"/>    
    </inertial>
  </link>
  <gazebo reference="front_right">
    <material>Gazebo/Black</material>
<!--     <mu1 value="0.000001"/>
    <mu2 value="0.000001"/> -->
  </gazebo>
  <!--Cylindre 1  -->
  <joint name="cylindre1_joint" type="fixed">
    <parent link="chassis1"/>
    <child link="cylindre1"/>
    <origin rpy="0 0 0" xyz="0.01 0.03 0.07"/>
  </joint>
  <link name="cylindre1">
    <visual>
      <geometry>
        <cylinder length="0.05" radius="0.003"/>
      </geometry>
      <material name="white"/>
    </visual>
    <collision>
      <geometry>
        <cylinder length="0.05" radius="0.003"/>
      </geometry>
    </collision>
    <inertial>
      <origin rpy="0.0 0.0 0.0" xyz="0.01 0.03 0.07"/>
      <mass value="0.000706858"/>
      <inertia ixx="1.4885251383333338e-07" ixy="0.0" ixz="0.0" iyy="1.4885251383333338e-07" iyz="0.0" izz="3.180861e-09"/>
    </inertial>
  </link>
  <gazebo reference="cylindre1">
    <material>Gazebo/White</material>
  </gazebo>
  <!--Cylindre 2  -->
  <joint name="cylindre2_joint" type="fixed">
    <parent link="chassis1"/>
    <child link="cylindre2"/>
    <origin rpy="0 0 0" xyz="0.01 -0.03 0.07"/>
  </joint>
  <link name="cylindre2">
    <visual>
      <geometry>
        <cylinder length="0.05" radius="0.003"/>
      </geometry>
      <material name="white"/>
    </visual>
    <collision>
      <geometry>
        <cylinder length="0.05" radius="0.003"/>
      </geometry>
    </collision>
    <inertial>
      <origin rpy="0.0 0.0 0.0" xyz="0.01 -0.03 0.07"/>
      <mass value="0.000706858"/>
      <inertia ixx="1.4885251383333338e-07" ixy="0.0" ixz="0.0" iyy="1.4885251383333338e-07" iyz="0.0" izz="3.180861e-09"/>
    </inertial>
  </link>
  <gazebo reference="cylindre2">
    <material>Gazebo/White</material>
  </gazebo>
  <!--Cylindre 3  -->
  <joint name="cylindre3_joint" type="fixed">
    <parent link="chassis5"/>
    <child link="cylindre3"/>
    <origin rpy="0 0 0" xyz="0.0125 -0.03 0.025"/>
  </joint>
  <link name="cylindre3">
    <visual>
      <geometry>
        <cylinder length="0.05" radius="0.003"/>
      </geometry>
      <material name="white"/>
    </visual>
    <collision>
      <geometry>
        <cylinder length="0.05" radius="0.003"/>
      </geometry>
    </collision>
    <inertial>
      <origin rpy="0.0 0.0 0.0" xyz="0.0125 -0.03 0.025"/>
      <mass value="0.000706858"/>
      <inertia ixx="1.4885251383333338e-07" ixy="0.0" ixz="0.0" iyy="1.4885251383333338e-07" iyz="0.0" izz="3.180861e-09"/>
    </inertial>
  </link>
  <gazebo reference="cylindre3">
    <material>Gazebo/White</material>
  </gazebo>
  <!--Cylindre 4  -->
  <joint name="cylindre4_joint" type="fixed">
    <parent link="chassis5"/>
    <child link="cylindre4"/>
    <origin rpy="0 0 0" xyz="0.0125 0.03 0.025"/>
  </joint>
  <link name="cylindre4">
    <visual>
      <geometry>
        <cylinder length="0.05" radius="0.003"/>
      </geometry>
      <material name="white"/>
    </visual>
    <collision>
      <geometry>
        <cylinder length="0.05" radius="0.003"/>
      </geometry>
    </collision>
    <inertial>
      <origin rpy="0.0 0.0 0.0" xyz="0.0125 0.03 0.025"/>
      <mass value="0.000706858"/>
      <inertia ixx="1.4885251383333338e-07" ixy="0.0" ixz="0.0" iyy="1.4885251383333338e-07" iyz="0.0" izz="3.180861e-09"/>
    </inertial>
  </link>
  <gazebo reference="cylindre4">
    <material>Gazebo/White</material>
  </gazebo>

  <joint name="base_link_front_laser_joint" type="fixed">
    <axis xyz="0 0 1"/>
    <origin rpy="0 0 0" xyz="0.25 0 0.13"/>
    <parent link="base_link"/>
    <child link="front_laser"/>
  </joint>
  <link name="front_laser">
    <collision>
      <origin rpy="0 0 0" xyz="0 0 0"/>
      <geometry>
        <box size="0.1 0.1 0.1"/>
      </geometry>
    </collision>
    <visual>
            <geometry>
                <cylinder radius="0.025" length="0.02"/>
            </geometry>
            <material name="green"/>
    </visual>
    <inertial>
      <mass value="1e-5"/>
      <origin rpy="0 0 0" xyz="0 0 0"/>
      <inertia ixx="1e-6" ixy="0" ixz="0" iyy="1e-6" iyz="0" izz="1e-6"/>
    </inertial>
  </link>

  <gazebo reference="front_laser">
    <sensor name="laser" type="ray">
      <pose>0 0 0 0 0 0</pose>
      <ray>
        <scan>
          <horizontal>
            <!-- The URG-04LX-UG01  has  683 steps with 0.35139 Degree resolution -->
            <resolution>1</resolution>
            <max_angle>2.0944</max_angle>
            <!--2.0944 120 Degree -->
            <min_angle>-2.0944</min_angle>
            <!-- -120 Degree -->
            <samples>360</samples>
            <!--<samples>683</samples>-->
          </horizontal>
        </scan>
        <range>
          <min>0.1</min>7
          <max>10</max>
          <resolution>0.05</resolution>
        </range>
      </ray>
      <plugin name='laser' filename='libgazebo_ros_ray_sensor.so'>
            <ros>
                <remapping>~/out:=/front_laser/scan</remapping>
            </ros>
          <output_type>sensor_msgs/LaserScan</output_type>
          <frame_name>front_laser</frame_name>
        </plugin>
      <!--
          <plugin name="laser" filename="libRayPlugin.so" />
          -->
      <always_on>1</always_on>
      <update_rate>100</update_rate>
      <visualize>false</visualize>
    </sensor>
  </gazebo>
      <gazebo>
    <plugin filename="libgazebo_ros_diff_drive.so" name="differential_drive_controller">
      <!-- <ros>
        <remapping>odom:=odom/unfiltered</remapping>
      </ros> -->
      <num_wheel_pairs>2</num_wheel_pairs>
      <left_joint>front_left_wheel_joint</left_joint>
      <right_joint>front_right_wheel_joint</right_joint>
      <left_joint>rear_left_wheel_joint</left_joint>
      <right_joint>rear_right_wheel_joint</right_joint>
      <wheel_separation>0.165</wheel_separation>
      <wheel_separation>0.165</wheel_separation>
      <wheel_diameter>0.067</wheel_diameter>
      <wheel_diameter>0.067</wheel_diameter>
      <updateRate>50.0</updateRate>
      <max_wheel_acceleration>0.3</max_wheel_acceleration>
      <robot_base_frame>base_link</robot_base_frame>
      <publish_odom>true</publish_odom>
      <publish_odom_tf>true</publish_odom_tf>
      <publish_wheel_tf>true</publish_wheel_tf>
      <odometry_frame>odom</odometry_frame>
    </plugin>
  </gazebo>
</robot>
